<?xml version="1.0"?>
<robot name="gen3">
  <link name="base_link"/>

  <joint name="joint_1" type="revolute">
    <parent link="base_link"/>
    <child link="link_1"/>
    <limit lower="-3.14" upper="3.14" effort="10" velocity="5"/>
  </joint>
  <link name="link_1"/>

  <joint name="joint_2" type="revolute">
    <parent link="link_1"/>
    <child link="link_2"/>
    <limit lower="-3.14" upper="3.14" effort="10" velocity="5"/>
  </joint>
  <link name="link_2"/>

  <joint name="joint_3" type="revolute">
    <parent link="link_2"/>
    <child link="link_3"/>
    <limit lower="-3.14" upper="3.14" effort="10" velocity="5"/>
  </joint>
  <link name="link_3"/>

  <joint name="joint_4" type="revolute">
    <parent link="link_3"/>
    <child link="link_4"/>
    <limit lower="-3.14" upper="3.14" effort="10" velocity="5"/>
  </joint>
  <link name="link_4"/>

  <joint name="joint_5" type="revolute">
    <parent link="link_4"/>
    <child link="link_5"/>
    <limit lower="-3.14" upper="3.14" effort="10" velocity="5"/>
  </joint>
  <link name="link_5"/>

  <joint name="joint_6" type="revolute">
    <parent link="link_5"/>
    <child link="link_6"/>
    <limit lower="-3.14" upper="3.14" effort="10" velocity="5"/>
  </joint>
  <link name="link_6"/>

  <joint name="joint_7" type="revolute">
    <parent link="link_6"/>
    <child link="link_7"/>
    <limit lower="-3.14" upper="3.14" effort="10" velocity="5"/>
  </joint>
  <link name="link_7"/>
</robot>

